<?xml version="1.0"?>

<robot name="leaphand_right">
  <!-- BASE -->
  <link name="palm_lower">
    <inertial>
      <origin xyz="0 0 0" rpy="0 0 0"/>
      <mass value="0.237"/>
      <inertia ixx="0.00035" ixy="0" ixz="0" iyy="0.00026" iyz="0" izz="0.00053"/>
    </inertial>
    <visual>
      <origin xyz="-0.020095249652862544332 0.025757756134899473244 -0.034722403578460216134" rpy="0 -0 0" />
      <geometry>
        <mesh filename="palm_lower.stl"/>
      </geometry>
      <material name="palm_lower_material">
        <color rgba="0.60392156862745094426 0.14901960784313725283 0.14901960784313725283 1.0"/>
      </material>
    </visual>
    <!-- <visual name="visual_0_palm_lower">
      <origin xyz="-0.02324 -0.03083 -0.01476" rpy="0 0 0"/>
      <geometry>
        <mesh filename="../meshes/dae/Palm Lower.dae" scale="1.0 1.0 1.0"/>
      </geometry>
      <material name="palm_lower_material"/>
    </visual> -->
    <collision name="collision_0_palm_lower">
      <origin xyz="-0.04856 -0.03756 -0.01126" rpy="3.14159 0 0"/>
      <geometry>
        <box size="0.10124 0.12469 0.04608"/>
      </geometry>
    </collision>
  </link>

  <link name="mcp_joint">
    <inertial>
      <origin xyz="0 0 0" rpy="0 0 0"/>
      <mass value="0.044"/>
      <inertia ixx="2e-05" ixy="0" ixz="0" iyy="2e-05" iyz="0" izz="2e-05"/>
    </inertial>
    <visual>
      <origin xyz="0.0084069022611744960438 0.0077662438597169954416 0.014657354985032912051" rpy="1.6375789613220999807e-15 -1.0210473302491019535e-30 1.7177968783327987474e-31" />
      <geometry>
        <mesh filename="mcp_joint.stl"/>
      </geometry>
      <material name="mcp_joint_material">
        <color rgba="0.86666666666666669627 0.86666666666666669627 0.050980392156862744391 1.0"/>
      </material>
    </visual>
    <!-- <visual name="visual_0_mcp_joint">
      <origin xyz="-0.01684 0.02792 0.01459" rpy="0 0 0"/>
      <geometry>
        <mesh filename="../meshes/dae/Mcp Joint.dae" scale="1.0 1.0 1.0"/>
      </geometry>
      <material name="mcp_joint_material"/>
    </visual> -->
    <collision name="collision_0_mcp_joint">
      <origin xyz="-0.02524 0.03613 0.01868" rpy="0 0 1.5708"/>
      <geometry>
        <box size="0.0527 0.0311 0.0273"/>
      </geometry>
    </collision>
  </link>

  <link name="pip">
    <inertial>
      <origin xyz="0 0 0" rpy="0 0 0"/>
      <mass value="0.032"/>
      <inertia ixx="2e-05" ixy="0" ixz="0" iyy="2e-05" iyz="0" izz="2e-05"/>
    </inertial>
    <visual>
      <origin xyz="0.0096433630922713280131 0.00029999999999998951117 0.00078403401041737645627" rpy="-1.570796326794896558 -1.570796326794896336 0" />
      <geometry>
        <mesh filename="pip.stl"/>
      </geometry>
      <material name="pip_material">
        <color rgba="0.74901960784313725839 0.74901960784313725839 0.74901960784313725839 1.0"/>
      </material>
    </visual>
    <!-- <visual name="visual_0_pip">
      <origin xyz="0.00967 0.00143 -0.00933" rpy="-1.5708 -1.5708 0"/>
      <geometry>
        <mesh filename="../meshes/dae/Pip.dae" scale="1.0 1.0 1.0"/>
      </geometry>
      <material name="pip_material"/>
    </visual> -->
    <collision name="collision_0_pip">
      <origin xyz="0.00689 0.0003 -0.01065" rpy="1.5708 0 -3.14159"/>
      <geometry>
        <box size="0.035 0.0245 0.0273"/>
      </geometry>
    </collision>
  </link>

  <link name="dip">
    <inertial>
      <origin xyz="0 0 0" rpy="0 0 0"/>
      <mass value="0.037"/>
      <inertia ixx="2e-05" ixy="0" ixz="0" iyy="2e-05" iyz="0" izz="2e-05"/>
    </inertial>
    <visual>
      <origin xyz="0.021133352895225002849 -0.0084321191467048792201 0.0097850881620952408213" rpy="-3.141592653589793116 4.5075111242164408299e-32 4.4395481053923607589e-32" />
      <geometry>
        <mesh filename="dip.stl"/>
      </geometry>
      <material name="dip_material">
        <color rgba="0.86666666666666669627 0.86666666666666669627 0.050980392156862744391 1.0"/>
      </material>
    </visual>
    <!-- <visual name="visual_0_dip">
      <origin xyz="0.00367 -0.02506 0.01354" rpy="3.14159 0 0"/>
      <geometry>
        <mesh filename="../meshes/dae/Dip.dae" scale="1.0 1.0 1.0"/>
      </geometry>
      <material name="dip_material"/>
    </visual> -->
    <collision name="collision_0_dip">
      <origin xyz="0.00721 -0.03424 0.01512" rpy="3.14159 0 1.5708"/>
      <geometry>
        <box size="0.0221 0.0342 0.0273"/>
      </geometry>
    </collision>
  </link>

  <link name="fingertip">
    <inertial>
      <origin xyz="0 0 0" rpy="0 0 0"/>
      <mass value="0.016"/>
      <inertia ixx="2e-05" ixy="0" ixz="0" iyy="2e-05" iyz="0" izz="2e-05"/>
    </inertial>
    <visual>
      <origin xyz="0.013286424108533503169 -0.0061142383865419869249 0.014499999999999497666" rpy="3.141592653589793116 1.1993117970061734707e-33 4.4395481053923607589e-32" />
      <geometry>
        <mesh filename="fingertip.stl"/>
      </geometry>
      <material name="fingertip_material">
        <color rgba="0.86666666666666669627 0.86666666666666669627 0.050980392156862744391 1.0"/>
      </material>
    </visual>
    <!-- <visual name="visual_0_fingertip">
      <origin xyz="-0.0007 -0.01414 0.01457" rpy="-3.14159 0 0"/>
      <geometry>
        <mesh filename="../meshes/dae/Fingertip.dae" scale="1.0 1.0 1.0"/>
      </geometry>
      <material name="fingertip_material"/>
    </visual> -->
    <collision name="collision_0_fingertip">
      <origin xyz="-0.00045 -0.03372 0.0145" rpy="-3.14159 0 1.5708"/>
      <geometry>
        <box size="0.0312 0.0229 0.0231"/>
      </geometry>
    </collision>
  </link>

  <joint name="0" type="revolute">
    <origin xyz="-0.0122 0.0381 0.0145" rpy="-1.5708 0 1.5708"/>
    <parent link="mcp_joint"/>
    <child link="pip"/>
    <axis xyz="0 0 -1.0"/>
    <limit lower="-1.047" upper="1.047" effort="0.95" velocity="8.48"/>
  </joint>

  <joint name="1" type="revolute">
    <origin xyz="-0.0071 0.02306 -0.01872" rpy="1.5708 1.5708 0"/>
    <parent link="palm_lower"/>
    <child link="mcp_joint"/>
    <axis xyz="0 0 -1.0"/>
    <limit lower="-0.314" upper="2.23" effort="0.95" velocity="8.48"/>
  </joint>

  <joint name="2" type="revolute">
    <origin xyz="0.015 0.0143 -0.013" rpy="1.5708 -1.5708 0"/>
    <parent link="pip"/>
    <child link="dip"/>
    <axis xyz="0 0 -1.0"/>
    <limit lower="-0.506" upper="1.885" effort="0.95" velocity="8.48"/>
  </joint>

  <joint name="3" type="revolute">
    <origin xyz="0 -0.0361 0.0002" rpy="0 0 0"/>
    <parent link="dip"/>
    <child link="fingertip"/>
    <axis xyz="0 0 -1.0"/>
    <limit lower="-0.366" upper="2.042" effort="0.95" velocity="8.48"/>
  </joint>

  <link name="mcp_joint_2">
    <inertial>
      <origin xyz="0 0 0" rpy="0 0 0"/>
      <mass value="0.044"/>
      <inertia ixx="2e-05" ixy="0" ixz="0" iyy="2e-05" iyz="0" izz="2e-05"/>
    </inertial>
    <!-- <visual name="visual_0_mcp_joint_2">
      <origin xyz="-0.01684 0.02792 0.01459" rpy="0 0 0"/>
      <geometry>
        <mesh filename="../meshes/dae/Mcp Joint.001.dae" scale="1.0 1.0 1.0"/>
      </geometry>
      <material name="mcp_joint_material"/>
    </visual> -->
    <visual>
      <origin xyz="0.0084069022611744960438 0.0077662438597169954416 0.014657354985032913786" rpy="1.6375789613220999807e-15 -1.0076465469034000467e-30 2.1209300131419907151e-61" />
      <geometry>
        <mesh filename="mcp_joint.stl"/>
      </geometry>
      <material name="mcp_joint_material">
        <color rgba="0.86666666666666669627 0.86666666666666669627 0.050980392156862744391 1.0"/>
      </material>
    </visual>
    <collision name="collision_0_mcp_joint_2">
      <origin xyz="-0.02524 0.03613 0.01868" rpy="0 0 1.5708"/>
      <geometry>
        <box size="0.0527 0.0311 0.0273"/>
      </geometry>
    </collision>
  </link>

  <link name="pip_2">
    <inertial>
      <origin xyz="0 0 0" rpy="0 0 0"/>
      <mass value="0.032"/>
      <inertia ixx="2e-05" ixy="0" ixz="0" iyy="2e-05" iyz="0" izz="2e-05"/>
    </inertial>
    <!-- <visual name="visual_0_pip_2">
      <origin xyz="0.00967 0.00143 -0.00933" rpy="-1.5708 -1.5708 0"/>
      <geometry>
        <mesh filename="../meshes/dae/Pip.001.dae" scale="1.0 1.0 1.0"/>
      </geometry>
      <material name="pip_material"/>
    </visual> -->
    <visual>
      <origin xyz="0.0096433630922713280131 0.00029999999999999471534 0.00078403401041737645627" rpy="-1.570796326794896558 -1.570796326794896336 0" />
      <geometry>
        <mesh filename="pip.stl"/>
      </geometry>
      <material name="pip_material">
        <color rgba="0.74901960784313725839 0.74901960784313725839 0.74901960784313725839 1.0"/>
      </material>
    </visual>
    <collision name="collision_0_pip_2">
      <origin xyz="0.00689 0.0003 -0.01065" rpy="1.5708 0 -3.14159"/>
      <geometry>
        <box size="0.035 0.0245 0.0273"/>
      </geometry>
    </collision>
  </link>

  <link name="dip_2">
    <inertial>
      <origin xyz="0 0 0" rpy="0 0 0"/>
      <mass value="0.037"/>
      <inertia ixx="2e-05" ixy="0" ixz="0" iyy="2e-05" iyz="0" izz="2e-05"/>
    </inertial>
    <!-- <visual name="visual_0_dip_2">
      <origin xyz="0.00367 -0.02506 0.01354" rpy="3.14159 0 0"/>
      <geometry>
        <mesh filename="../meshes/dae/Dip.001.dae" scale="1.0 1.0 1.0"/>
      </geometry>
      <material name="dip_material"/>
    </visual> -->
    <visual>
      <origin xyz="0.021133352895225002849 -0.0084321191467048653423 0.0097850881620952373519" rpy="-3.141592653589793116 2.1146933785271955805e-32 1.4408183216511868558e-31" />
      <geometry>
        <mesh filename="dip.stl"/>
      </geometry>
      <material name="dip_material">
        <color rgba="0.86666666666666669627 0.86666666666666669627 0.050980392156862744391 1.0"/>
      </material>
    </visual>
    <collision name="collision_0_dip_2">
      <origin xyz="0.00721 -0.03424 0.01512" rpy="3.14159 0 1.5708"/>
      <geometry>
        <box size="0.0221 0.0342 0.0273"/>
      </geometry>
    </collision>
  </link>

  <link name="fingertip_2">
    <inertial>
      <origin xyz="0 0 0" rpy="0 0 0"/>
      <mass value="0.016"/>
      <inertia ixx="2e-05" ixy="0" ixz="0" iyy="2e-05" iyz="0" izz="2e-05"/>
    </inertial>
    <!-- <visual name="visual_0_fingertip_2">
      <origin xyz="-0.0007 -0.01414 0.01457" rpy="-3.14159 0 0"/>
      <geometry>
        <mesh filename="../meshes/dae/Fingertip.001.dae" scale="1.0 1.0 1.0"/>
      </geometry>
      <material name="fingertip_material"/>
    </visual> -->
    <visual>
      <origin xyz="0.01328642410853349623 -0.0061142383865420008027 0.014499999999999495931" rpy="3.141592653589793116 -4.3179597882835943107e-33 1.4408183216511868558e-31" />
      <geometry>
        <mesh filename="fingertip.stl"/>
      </geometry>
    <material name="fingertip_material">
      <color rgba="0.86666666666666669627 0.86666666666666669627 0.050980392156862744391 1.0"/>
    </material>
    </visual>
    <collision name="collision_0_fingertip_2">
      <origin xyz="-0.00045 -0.03372 0.0145" rpy="-3.14159 0 1.5708"/>
      <geometry>
        <box size="0.0312 0.0229 0.0231"/>
      </geometry>
    </collision>
  </link>

  <joint name="4" type="revolute">
    <origin xyz="-0.0122 0.0381 0.0145" rpy="-1.5708 0 1.5708"/>
    <parent link="mcp_joint_2"/>
    <child link="pip_2"/>
    <axis xyz="0 0 -1.0"/>
    <limit lower="-1.047" upper="1.047" effort="0.95" velocity="8.48"/>
  </joint>

  <joint name="5" type="revolute">
    <origin xyz="-0.0071 -0.02239 -0.01872" rpy="1.5708 1.5708 0"/>
    <parent link="palm_lower"/>
    <child link="mcp_joint_2"/>
    <axis xyz="0 0 -1.0"/>
    <limit lower="-0.314" upper="2.23" effort="0.95" velocity="8.48"/>
  </joint>

  <joint name="6" type="revolute">
    <origin xyz="0.015 0.0143 -0.013" rpy="1.5708 -1.5708 0"/>
    <parent link="pip_2"/>
    <child link="dip_2"/>
    <axis xyz="0 0 -1.0"/>
    <limit lower="-0.506" upper="1.885" effort="0.95" velocity="8.48"/>
  </joint>

  <joint name="7" type="revolute">
    <origin xyz="0 -0.0361 0.0002" rpy="0 0 0"/>
    <parent link="dip_2"/>
    <child link="fingertip_2"/>
    <axis xyz="0 0 -1.0"/>
    <limit lower="-0.366" upper="2.042" effort="0.95" velocity="8.48"/>
  </joint>

  <link name="mcp_joint_3">
    <inertial>
      <origin xyz="0 0 0" rpy="0 0 0"/>
      <mass value="0.044"/>
      <inertia ixx="2e-05" ixy="0" ixz="0" iyy="2e-05" iyz="0" izz="2e-05"/>
    </inertial>
    <!-- <visual name="visual_0_mcp_joint_3">
      <origin xyz="-0.01684 0.02792 0.01459" rpy="0 0 0"/>
      <geometry>
        <mesh filename="../meshes/dae/Mcp Joint.002.dae" scale="1.0 1.0 1.0"/>
      </geometry>
      <material name="mcp_joint_material"/>
    </visual> -->
    <visual>
      <origin xyz="0.0084069022611744995133 0.0077662438597169963089 0.014657354985032913786" rpy="1.6375789613220999807e-15 -1.0059504988632626953e-30 5.729641584552035421e-32" />
      <geometry>
        <mesh filename="mcp_joint.stl"/>
      </geometry>
      <material name="mcp_joint_material">
        <color rgba="0.86666666666666669627 0.86666666666666669627 0.050980392156862744391 1.0"/>
      </material>
    </visual>
    <collision name="collision_0_mcp_joint_3">
      <origin xyz="-0.02524 0.03613 0.01868" rpy="0 0 1.5708"/>
      <geometry>
        <box size="0.0527 0.0311 0.0273"/>
      </geometry>
    </collision>
  </link>

  <link name="pip_3">
    <inertial>
      <origin xyz="0 0 0" rpy="0 0 0"/>
      <mass value="0.032"/>
      <inertia ixx="2e-05" ixy="0" ixz="0" iyy="2e-05" iyz="0" izz="2e-05"/>
    </inertial>
    <!-- <visual name="visual_0_pip_3">
      <origin xyz="0.00967 0.00143 -0.00933" rpy="-1.5708 -1.5708 0"/>
      <geometry>
        <mesh filename="../meshes/dae/Pip.002.dae" scale="1.0 1.0 1.0"/>
      </geometry>
      <material name="pip_material"/>
    </visual> -->
    <visual>
      <origin xyz="0.0096433630922713314826 0.00029999999999998083755 0.00078403401041737645627" rpy="-1.570796326794896558 -1.570796326794896336 0" />
      <geometry>
        <mesh filename="pip.stl"/>
      </geometry>
      <material name="pip_material">
        <color rgba="0.74901960784313725839 0.74901960784313725839 0.74901960784313725839 1.0"/>
      </material>
    </visual>
    <collision name="collision_0_pip_3">
      <origin xyz="0.00689 0.0003 -0.01065" rpy="1.5708 0 -3.14159"/>
      <geometry>
        <box size="0.035 0.0245 0.0273"/>
      </geometry>
    </collision>
  </link>

  <link name="dip_3">
    <inertial>
      <origin xyz="0 0 0" rpy="0 0 0"/>
      <mass value="0.037"/>
      <inertia ixx="2e-05" ixy="0" ixz="0" iyy="2e-05" iyz="0" izz="2e-05"/>
    </inertial>
    <!-- <visual name="visual_0_dip_3">
      <origin xyz="0.00367 -0.02506 0.01354" rpy="3.14159 0 0"/>
      <geometry>
        <mesh filename="../meshes/dae/Dip.002.dae" scale="1.0 1.0 1.0"/>
      </geometry>
      <material name="dip_material"/>
    </visual> -->
    <visual>
      <origin xyz="0.021133352895225006318 -0.0084321191467048653423 0.0097850881620952373519" rpy="-3.141592653589793116 -1.4095651113919093005e-33 1.5565411607615035382e-32" />
      <geometry>
        <mesh filename="dip.stl"/>
      </geometry>
      <material name="dip_material">
        <color rgba="0.86666666666666669627 0.86666666666666669627 0.050980392156862744391 1.0"/>
      </material>
    </visual>
    <collision name="collision_0_dip_3">
      <origin xyz="0.00721 -0.03424 0.01512" rpy="3.14159 0 1.5708"/>
      <geometry>
        <box size="0.0221 0.0342 0.0273"/>
      </geometry>
    </collision>
  </link>

  <link name="fingertip_3">
    <inertial>
      <origin xyz="0 0 0" rpy="0 0 0"/>
      <mass value="0.016"/>
      <inertia ixx="2e-05" ixy="0" ixz="0" iyy="2e-05" iyz="0" izz="2e-05"/>
    </inertial>
    <!-- <visual name="visual_0_fingertip_3">
      <origin xyz="-0.0007 -0.01414 0.01457" rpy="-3.14159 0 0"/>
      <geometry>
        <mesh filename="../meshes/dae/Fingertip.002.dae" scale="1.0 1.0 1.0"/>
      </geometry>
      <material name="fingertip_material"/>
    </visual> -->
    <visual>
      <origin xyz="0.013286424108533501434 -0.0061142383865419869249 0.0144999999999994994" rpy="3.141592653589793116 8.6170716950575402125e-33 1.5565411607615035382e-32" />
      <geometry>
        <mesh filename="fingertip.stl"/>
      </geometry>
      <material name="fingertip_material">
        <color rgba="0.86666666666666669627 0.86666666666666669627 0.050980392156862744391 1.0"/>
      </material>
    </visual>
    <collision name="collision_0_fingertip_3">
      <origin xyz="-0.00045 -0.03372 0.0145" rpy="3.14159 0 1.5708"/>
      <geometry>
        <box size="0.0312 0.0229 0.0231"/>
      </geometry>
    </collision>
  </link>

  <joint name="8" type="revolute">
    <origin xyz="-0.0122 0.0381 0.0145" rpy="-1.5708 0 1.5708"/>
    <parent link="mcp_joint_3"/>
    <child link="pip_3"/>
    <axis xyz="0 0 -1.0"/>
    <limit lower="-1.047" upper="1.047" effort="0.95" velocity="8.48"/>
  </joint>

  <joint name="9" type="revolute">
    <origin xyz="-0.0071 -0.06784 -0.01872" rpy="1.5708 1.5708 0"/>
    <parent link="palm_lower"/>
    <child link="mcp_joint_3"/>
    <axis xyz="0 0 -1.0"/>
    <limit lower="-0.314" upper="2.23" effort="0.95" velocity="8.48"/>
  </joint>

  <joint name="10" type="revolute">
    <origin xyz="0.015 0.0143 -0.013" rpy="1.5708 -1.5708 0"/>
    <parent link="pip_3"/>
    <child link="dip_3"/>
    <axis xyz="0 0 -1.0"/>
    <limit lower="-0.506" upper="1.885" effort="0.95" velocity="8.48"/>
  </joint>

  <joint name="11" type="revolute">
    <origin xyz="0 -0.0361 0.0002" rpy="0 0 0"/>
    <parent link="dip_3"/>
    <child link="fingertip_3"/>
    <axis xyz="0 0 -1.0"/>
    <limit lower="-0.366" upper="2.042" effort="0.95" velocity="8.48"/>
  </joint>

  <link name="pip_4">
    <inertial>
      <origin xyz="0 0 0" rpy="0 0 0"/>
      <mass value="0.032"/>
      <inertia ixx="2e-05" ixy="0" ixz="0" iyy="2e-05" iyz="0" izz="2e-05"/>
    </inertial>
    <!-- <visual name="visual_0_pip_4">
      <origin xyz="-0.00533 0.00143 -0.00933" rpy="-1.5708 -1.5708 0"/>
      <geometry>
        <mesh filename="../meshes/dae/Pip.003.dae" scale="1.0 1.0 1.0"/>
      </geometry>
      <material name="pip_material"/>
    </visual> -->
    <visual>
      <origin xyz="-0.0053566369077286714317 0.00029999999999999991951 0.00078403401041737819099" rpy="-1.570796326794896558 -1.570796326794896336 0" />
      <geometry>
        <mesh filename="pip.stl"/>
      </geometry>
      <material name="pip_material">
        <color rgba="0.74901960784313725839 0.74901960784313725839 0.74901960784313725839 1.0"/>
      </material>
    </visual>
    <collision name="collision_0_pip_4">
      <origin xyz="-0.008 0 -0.01169" rpy="1.5708 -1.5708 0"/>
      <geometry>
        <box size="0.0228 0.0348 0.0273"/>
      </geometry>
    </collision>
  </link>

  <link name="thumb_pip">
    <inertial>
      <origin xyz="0 0 0" rpy="0 0 0"/>
      <mass value="0.003"/>
      <inertia ixx="2e-05" ixy="0" ixz="0" iyy="2e-05" iyz="0" izz="2e-05"/>
    </inertial>
    <!-- <visual name="visual_0_thumb_pip">
      <origin xyz="-2e-05 3e-05 -0.00752" rpy="1.5708 0 0"/>
      <geometry>
        <mesh filename="../meshes/dae/Thumb Pip.dae" scale="1.0 1.0 1.0"/>
      </geometry>
      <material name="thumb_pip_material"/>
    </visual> -->
    <visual>
      <origin xyz="0.011961920770611186859 -5.3082538364890297089e-16 -0.015852648956664199681" rpy="1.570796326794896558 1.6050198443300152637e-46 -3.9204996250525192755e-59" />
      <geometry>
        <mesh filename="thumb_pip.stl"/>
      </geometry>
      <material name="thumb_pip_material">
        <color rgba="0.86666666666666669627 0.86666666666666669627 0.050980392156862744391 1.0"/>
      </material>
    </visual>
    <collision name="collision_0_thumb_pip">
      <origin xyz="0 -0.00024 -0.01195" rpy="0 0 0"/>
      <geometry>
        <box size="0.0295 0.034 0.0235"/>
      </geometry>
    </collision>
  </link>

  <link name="thumb_dip">
    <inertial>
      <origin xyz="0 0 0" rpy="0 0 0"/>
      <mass value="0.038"/>
      <inertia ixx="2e-05" ixy="0" ixz="0" iyy="2e-05" iyz="0" izz="2e-05"/>
    </inertial>
    <!-- <visual name="visual_0_thumb_dip">
      <origin xyz="-0.00014 0.01911 -0.01325" rpy="0 0 0"/>
      <geometry>
        <mesh filename="../meshes/dae/Thumb Dip.dae" scale="1.0 1.0 1.0"/>
      </geometry>
      <material name="thumb_dip_material"/>
    </visual> -->
    <visual>
      <origin xyz="0.043968715707239175439 0.057952952973709198625 -0.0086286764493694757122" rpy="1.9428902930940098942e-16 3.2751579226442200773e-15 1.1123758529657360012e-46" />
      <geometry>
        <mesh filename="thumb_dip.stl"/>
      </geometry>
      <material name="thumb_dip_material">
        <color rgba="0.86666666666666669627 0.86666666666666669627 0.050980392156862744391 1.0"/>
      </material>
    </visual>
    <collision name="collision_0_thumb_dip">
      <origin xyz="-0.00358 0.02211 -0.01466" rpy="1.5708 0 0"/>
      <geometry>
        <box size="0.0295 0.0258 0.03032"/>
      </geometry>
    </collision>
  </link>

  <link name="thumb_fingertip">
    <inertial>
      <origin xyz="0 0 0" rpy="0 0 0"/>
      <mass value="0.049"/>
      <inertia ixx="4e-05" ixy="0" ixz="0" iyy="2e-05" iyz="0" izz="4e-05"/>
    </inertial>
    <!-- <visual name="visual_0_thumb_fingertip">
      <origin xyz="-0.00017 -0.01448 -0.0129" rpy="0 0 0"/>
      <geometry>
        <mesh filename="../meshes/dae/Thumb Fingertip.dae" scale="1.0 1.0 1.0"/>
      </geometry>
      <material name="thumb_fingertip_material"/>
    </visual> -->
    <visual>
      <origin xyz="0.062559538462667388381 0.078459682911396988469 0.048992911807332215068" rpy="4.3790577010156367543e-47 -3.3306690738754701143e-16 1.2042408677791935383e-46" />
      <geometry>
        <mesh filename="thumb_fingertip.stl"/>
      </geometry>
      <material name="thumb_fingertip_material">
        <color rgba="0.60392156862745094426 0.14901960784313725283 0.14901960784313725283 1.0"/>
      </material>
    </visual>
    <collision name="collision_0_thumb_fingertip">
      <origin xyz="0.00386 -0.02606 -0.01551" rpy="1.5708 0 0"/>
      <geometry>
        <box size="0.0295 0.0258 0.0665"/>
      </geometry>
    </collision>
  </link>

  <joint name="12" type="revolute">
    <origin xyz="-0.0694 -0.00124 -0.02162" rpy="0 1.5708 0"/>
    <parent link="palm_lower"/>
    <child link="pip_4"/>
    <axis xyz="0 0 -1.0"/>
    <limit lower="-0.349" upper="2.094" effort="0.95" velocity="8.48"/>
  </joint>

  <joint name="13" type="revolute">
    <origin xyz="0 0.0143 -0.013" rpy="1.5708 -1.5708 0"/>
    <parent link="pip_4"/>
    <child link="thumb_pip"/>
    <axis xyz="0 0 -1.0"/>
    <limit lower="-0.47" upper="2.443" effort="0.95" velocity="8.48"/>
  </joint>

  <joint name="14" type="revolute">
    <origin xyz="0 0.0145 -0.017" rpy="-1.5708 0 0"/>
    <parent link="thumb_pip"/>
    <child link="thumb_dip"/>
    <axis xyz="0 0 -1.0"/>
    <limit lower="-1.2" upper="1.9" effort="0.95" velocity="8.48"/>
  </joint>

  <joint name="15" type="revolute">
    <origin xyz="0 0.0466 0.0002" rpy="0 0 -3.14159"/>
    <parent link="thumb_dip"/>
    <child link="thumb_fingertip"/>
    <axis xyz="0 0 -1.0"/>
    <limit lower="-1.34" upper="1.88" effort="0.95" velocity="8.48"/>
  </joint>

    <!-- <material name="dip_material">
      <color rgba="0.86667 0.86667 0.05098 1.0"/>
    </material>

    <material name="fingertip_material">
      <color rgba="0.86667 0.86667 0.05098 1.0"/>
    </material>

    <material name="mcp_joint_material">
      <color rgba="0.86667 0.86667 0.05098 1.0"/>
    </material>

    <material name="palm_lower_material">
      <color rgba="0.60392 0.14902 0.14902 1.0"/>
    </material>

    <material name="pip_material">
      <color rgba="0.74902 0.74902 0.74902 1.0"/>
    </material>

    <material name="thumb_dip_material">
      <color rgba="0.86667 0.86667 0.05098 1.0"/>
    </material>

    <material name="thumb_fingertip_material">
      <color rgba="0.60392 0.14902 0.14902 1.0"/>
    </material>

    <material name="thumb_pip_material">
      <color rgba="0.86667 0.86667 0.05098 1.0"/>
    </material> -->

</robot>
